Workbook

Sheet Budget
A1: Halloween Animatronic — budget
A2: Halloween 2026 build. Totals update from the Purchases tab.
A4: Budget cap ($) | C4: ← enter your total budget
A5: Spent: ordered + arrived ($) | B5: =SUMIFS(Purchases!$F$5:$F$80,Purchases!$G$5:$G$80,"Ordered")+SUMIFS(Purchases!$F$5:$F$80,Purchases!$G$5:$G$80,"Arrived") -> 323.66
A6: Still to buy, priced so far ($) | B6: =SUMIFS(Purchases!$F$5:$F$80,Purchases!$G$5:$G$80,"To buy") -> 91.53
A7: Projected total ($) | B7: =B5+B6 -> 415.19
A8: Left in budget ($) | B8: =IF(B4="","",B4-B7)
A9: Rows still missing a price | B9: =SUMPRODUCT((Purchases!$G$5:$G$80<>"Returned")*(Purchases!$G$5:$G$80<>"")*(Purchases!$D$5:$D$80="")) -> 24
A10: Items still to buy | B10: =COUNTIF(Purchases!$G$5:$G$80,"To buy") -> 16
A13: By category
A14: Category | B14: Spent ($) | C14: To buy ($) | D14: Total ($) | E14: Unpriced rows
A15: =Lists!A2 -> Servos | B15: =SUMIFS(Purchases!$F$5:$F$80,Purchases!$A$5:$A$80,A15,Purchases!$G$5:$G$80,"Ordered")+SUMIFS(Purchases!$F$5:$F$80,Purchases!$A$5:$A$80,A15,Purchases!$G$5:$G$80,"Arrived") -> 0 | C15: =SUMIFS(Purchases!$F$5:$F$80,Purchases!$A$5:$A$80,A15,Purchases!$G$5:$G$80,"To buy") -> 0 | D15: =B15+C15 -> 0 | E15: =SUMPRODUCT((Purchases!$A$5:$A$80=A15)*(Purchases!$G$5:$G$80<>"Returned")*(Purchases!$D$5:$D$80="")) -> 2
A16: =Lists!A3 -> Electronics | B16: =SUMIFS(Purchases!$F$5:$F$80,Purchases!$A$5:$A$80,A16,Purchases!$G$5:$G$80,"Ordered")+SUMIFS(Purchases!$F$5:$F$80,Purchases!$A$5:$A$80,A16,Purchases!$G$5:$G$80,"Arrived") -> 0 | C16: =SUMIFS(Purchases!$F$5:$F$80,Purchases!$A$5:$A$80,A16,Purchases!$G$5:$G$80,"To buy") -> 0 | D16: =B16+C16 -> 0 | E16: =SUMPRODUCT((Purchases!$A$5:$A$80=A16)*(Purchases!$G$5:$G$80<>"Returned")*(Purchases!$D$5:$D$80="")) -> 3
A17: =Lists!A4 -> Power | B17: =SUMIFS(Purchases!$F$5:$F$80,Purchases!$A$5:$A$80,A17,Purchases!$G$5:$G$80,"Ordered")+SUMIFS(Purchases!$F$5:$F$80,Purchases!$A$5:$A$80,A17,Purchases!$G$5:$G$80,"Arrived") -> 0 | C17: =SUMIFS(Purchases!$F$5:$F$80,Purchases!$A$5:$A$80,A17,Purchases!$G$5:$G$80,"To buy") -> 0 | D17: =B17+C17 -> 0 | E17: =SUMPRODUCT((Purchases!$A$5:$A$80=A17)*(Purchases!$G$5:$G$80<>"Returned")*(Purchases!$D$5:$D$80="")) -> 2
A18: =Lists!A5 -> Audio | B18: =SUMIFS(Purchases!$F$5:$F$80,Purchases!$A$5:$A$80,A18,Purchases!$G$5:$G$80,"Ordered")+SUMIFS(Purchases!$F$5:$F$80,Purchases!$A$5:$A$80,A18,Purchases!$G$5:$G$80,"Arrived") -> 0 | C18: =SUMIFS(Purchases!$F$5:$F$80,Purchases!$A$5:$A$80,A18,Purchases!$G$5:$G$80,"To buy") -> 0 | D18: =B18+C18 -> 0 | E18: =SUMPRODUCT((Purchases!$A$5:$A$80=A18)*(Purchases!$G$5:$G$80<>"Returned")*(Purchases!$D$5:$D$80="")) -> 2
A19: =Lists!A6 -> Hardware | B19: =SUMIFS(Purchases!$F$5:$F$80,Purchases!$A$5:$A$80,A19,Purchases!$G$5:$G$80,"Ordered")+SUMIFS(Purchases!$F$5:$F$80,Purchases!$A$5:$A$80,A19,Purchases!$G$5:$G$80,"Arrived") -> 0 | C19: =SUMIFS(Purchases!$F$5:$F$80,Purchases!$A$5:$A$80,A19,Purchases!$G$5:$G$80,"To buy") -> 50.69 | D19: =B19+C19 -> 50.69 | E19: =SUMPRODUCT((Purchases!$A$5:$A$80=A19)*(Purchases!$G$5:$G$80<>"Returned")*(Purchases!$D$5:$D$80="")) -> 3
A20: =Lists!A7 -> Silicone & skin | B20: =SUMIFS(Purchases!$F$5:$F$80,Purchases!$A$5:$A$80,A20,Purchases!$G$5:$G$80,"Ordered")+SUMIFS(Purchases!$F$5:$F$80,Purchases!$A$5:$A$80,A20,Purchases!$G$5:$G$80,"Arrived") -> 58.53 | C20: =SUMIFS(Purchases!$F$5:$F$80,Purchases!$A$5:$A$80,A20,Purchases!$G$5:$G$80,"To buy") -> 30.98 | D20: =B20+C20 -> 89.51 | E20: =SUMPRODUCT((Purchases!$A$5:$A$80=A20)*(Purchases!$G$5:$G$80<>"Returned")*(Purchases!$D$5:$D$80="")) -> 4
A21: =Lists!A8 -> Mold-making | B21: =SUMIFS(Purchases!$F$5:$F$80,Purchases!$A$5:$A$80,A21,Purchases!$G$5:$G$80,"Ordered")+SUMIFS(Purchases!$F$5:$F$80,Purchases!$A$5:$A$80,A21,Purchases!$G$5:$G$80,"Arrived") -> 63.91 | C21: =SUMIFS(Purchases!$F$5:$F$80,Purchases!$A$5:$A$80,A21,Purchases!$G$5:$G$80,"To buy") -> 0 | D21: =B21+C21 -> 63.91 | E21: =SUMPRODUCT((Purchases!$A$5:$A$80=A21)*(Purchases!$G$5:$G$80<>"Returned")*(Purchases!$D$5:$D$80="")) -> 1
A22: =Lists!A9 -> Sculpting | B22: =SUMIFS(Purchases!$F$5:$F$80,Purchases!$A$5:$A$80,A22,Purchases!$G$5:$G$80,"Ordered")+SUMIFS(Purchases!$F$5:$F$80,Purchases!$A$5:$A$80,A22,Purchases!$G$5:$G$80,"Arrived") -> 0 | C22: =SUMIFS(Purchases!$F$5:$F$80,Purchases!$A$5:$A$80,A22,Purchases!$G$5:$G$80,"To buy") -> 0 | D22: =B22+C22 -> 0 | E22: =SUMPRODUCT((Purchases!$A$5:$A$80=A22)*(Purchases!$G$5:$G$80<>"Returned")*(Purchases!$D$5:$D$80="")) -> 1
A23: =Lists!A10 -> Finishing | B23: =SUMIFS(Purchases!$F$5:$F$80,Purchases!$A$5:$A$80,A23,Purchases!$G$5:$G$80,"Ordered")+SUMIFS(Purchases!$F$5:$F$80,Purchases!$A$5:$A$80,A23,Purchases!$G$5:$G$80,"Arrived") -> 129.99 | C23: =SUMIFS(Purchases!$F$5:$F$80,Purchases!$A$5:$A$80,A23,Purchases!$G$5:$G$80,"To buy") -> 0 | D23: =B23+C23 -> 129.99 | E23: =SUMPRODUCT((Purchases!$A$5:$A$80=A23)*(Purchases!$G$5:$G$80<>"Returned")*(Purchases!$D$5:$D$80="")) -> 3
A24: =Lists!A11 -> Enclosure | B24: =SUMIFS(Purchases!$F$5:$F$80,Purchases!$A$5:$A$80,A24,Purchases!$G$5:$G$80,"Ordered")+SUMIFS(Purchases!$F$5:$F$80,Purchases!$A$5:$A$80,A24,Purchases!$G$5:$G$80,"Arrived") -> 0 | C24: =SUMIFS(Purchases!$F$5:$F$80,Purchases!$A$5:$A$80,A24,Purchases!$G$5:$G$80,"To buy") -> 0 | D24: =B24+C24 -> 0 | E24: =SUMPRODUCT((Purchases!$A$5:$A$80=A24)*(Purchases!$G$5:$G$80<>"Returned")*(Purchases!$D$5:$D$80="")) -> 1
A25: =Lists!A12 -> Tools & workshop | B25: =SUMIFS(Purchases!$F$5:$F$80,Purchases!$A$5:$A$80,A25,Purchases!$G$5:$G$80,"Ordered")+SUMIFS(Purchases!$F$5:$F$80,Purchases!$A$5:$A$80,A25,Purchases!$G$5:$G$80,"Arrived") -> 71.23 | C25: =SUMIFS(Purchases!$F$5:$F$80,Purchases!$A$5:$A$80,A25,Purchases!$G$5:$G$80,"To buy") -> 9.86 | D25: =B25+C25 -> 81.09 | E25: =SUMPRODUCT((Purchases!$A$5:$A$80=A25)*(Purchases!$G$5:$G$80<>"Returned")*(Purchases!$D$5:$D$80="")) -> 2
A26: Total | B26: =SUM(B15:B25) -> 323.66 | C26: =SUM(C15:C25) -> 91.53 | D26: =SUM(D15:D25) -> 415.19 | E26: =SUM(E15:E25) -> 24
A28: How to use: in Purchases, fill the blue cells (Qty, Unit price, Shipping & tax, Link) and set Status. Example row: Qty 2, Unit price 18.99, Shipping & tax 2.47 → Total 40.45.
A29: Rows marked "To buy" are shaded amber; "Arrived" rows are shaded green. Prices are blank until you send the links.

Sheet Purchases
A1: Halloween Animatronic — purchases
A2: Blue cells are inputs: fill in Unit price, Shipping & tax and Link for each row. Total is calculated. Add new rows inside the table (above row 80).
A4: Category | B4: Item | C4: Qty | D4: Unit price ($) | E4: Shipping & tax ($) | F4: Total ($) | G4: Status | H4: Arrives | I4: Store | J4: Link | K4: Tracker task | L4: Notes
A5: Silicone & skin | B5: Nylon mesh fabric (black) | C5: 1 | F5: =IF(AND(D5="",E5=""),"",C5*D5+E5) | G5: Ordered | H5: Thu Oct 15 | I5: Amazon | K5: P2: nylon mesh & fabric | L5: Snap-pad reinforcement.
A6: Electronics | B6: Raspberry Pi Pico | C6: 2 | F6: =IF(AND(D6="",E6=""),"",C6*D6+E6) | G6: Ordered | H6: Thu Oct 15 | I6: Amazon | K6: P2: two Pico H
A7: Hardware | B7: Screw and nut assortment kit | C7: 1 | F7: =IF(AND(D7="",E7=""),"",C7*D7+E7) | G7: Ordered | H7: Thu Oct 15 | I7: Amazon | K7: P2: screws, bolts, washers, inserts | L7: Check it covers M2/M3/M4. Shoulder bolts are probably separate.
A8: Tools & workshop | B8: Clamp-arm ring light desk lamp | C8: 1 | F8: =IF(AND(D8="",E8=""),"",C8*D8+E8) | G8: Ordered | H8: Thu Oct 15 | I8: Amazon
A9: Hardware | B9: Brass heat-set insert assortment | C9: 1 | F9: =IF(AND(D9="",E9=""),"",C9*D9+E9) | G9: Ordered | H9: Thu Oct 15 | I9: Amazon | K9: P2: screws, bolts, washers, inserts
A10: Silicone & skin | B10: Nylon webbing strap (black) | C10: 1 | F10: =IF(AND(D10="",E10=""),"",C10*D10+E10) | G10: Ordered | H10: Thu Oct 15 | I10: Amazon | K10: P2: nylon mesh & fabric | L10: Stronger fabric tab for snap Test B.
A11: Finishing | B11: EOVEA shaggy faux fur fabric (grey) | C11: 1 | F11: =IF(AND(D11="",E11=""),"",C11*D11+E11) | G11: Ordered | I11: Amazon | K11: P11: hair (after Halloween) | L11: Arrival date not in the screenshot.
A12: Electronics | B12: Raspberry Pi Pico board with headers (listing 1) | C12: 1 | F12: =IF(AND(D12="",E12=""),"",C12*D12+E12) | G12: Ordered | H12: Sat Oct 17 | I12: Amazon
A13: Electronics | B13: Raspberry Pi Pico board with headers (listing 2) | C13: 1 | F13: =IF(AND(D13="",E13=""),"",C13*D13+E13) | G13: Ordered | H13: Sat Oct 17 | I13: Amazon
A14: Finishing | B14: Smooth-On Silc Pig pigment set | C14: 1 | F14: =IF(AND(D14="",E14=""),"",C14*D14+E14) | G14: Ordered | H14: Sat Oct 17 | I14: Amazon | K14: P2: silicone pigments
A15: Servos | B15: MG90S micro servo pack | C15: 2 | F15: =IF(AND(D15="",E15=""),"",C15*D15+E15) | G15: Ordered | H15: Sat Oct 17 | I15: Amazon | K15: P2: receive & inspect servos | L15: Qty = 2 packs. Put the pack price in Unit price.
A16: Servos | B16: MG996R servo 4-pack | C16: 1 | F16: =IF(AND(D16="",E16=""),"",C16*D16+E16) | G16: Ordered | H16: Sat Oct 17 | I16: Amazon | K16: P2: receive & inspect servos
A17: Mold-making | B17: Ultracal 30 gypsum cement | C17: 1 | F17: =IF(AND(D17="",E17=""),"",C17*D17+E17) | G17: Ordered | H17: Sat Oct 17 | I17: Amazon | K17: P2: gypsum mold material | L17: Needed by Oct 23.
A18: Hardware | B18: 7 mm sew-on snaps | C18: 1 | F18: =IF(AND(D18="",E18=""),"",C18*D18+E18) | G18: Ordered | K18: P2/P6: sew-on snaps | L18: Ticked as ordered in the tracker; not in the screenshots.
A19: Silicone & skin | B19: Ecoflex 00-30 (or PlatSil Gel-OO30): NOT BUYING | C19: 1 | F19: =IF(AND(D19="",E19=""),"",C19*D19+E19) | K19: P2: silicone | L19: Replaced by Dragon Skin FX-Pro (row 30), the project's skin silicone from 10/24 (PLAN D21). Status left blank so it drops out of the totals.
A20: Silicone & skin | B20: Mold release, sealer and silicone thickener | C20: 1 | F20: =IF(AND(D20="",E20=""),"",C20*D20+E20) | G20: To buy | K20: P2: thickener, sealer, release | L20: Mostly covered: Ease Release 200 (row 31), Cab-O-Sil (37), THI-VEX (40). Still to buy: a SAFE mold sealer (acrylic spray e.g. Krylon Crystal Clear, or petroleum jelly). Not shellac.
A21: Tools & workshop | B21: Mixing cups, sticks, brushes, scale, gloves | C21: 1 | F21: =IF(AND(D21="",E21=""),"",C21*D21+E21) | G21: To buy | K21: P2: mixing & mold tools | L21: Needed Sat Oct 17.
A22: Sculpting | B22: Monster Clay, 6 lb | C22: 1 | F22: =IF(AND(D22="",E22=""),"",C22*D22+E22) | G22: Arrived | K22: P2: sculpting clay | L22: Bought Oct 15 (Michaels); price not recorded. The face is sculpted in it.
A23: Power | B23: 20 V to 5–6 V buck converter for servos | C23: 1 | F23: =IF(AND(D23="",E23=""),"",C23*D23+E23) | G23: To buy | K23: P13: servo regulator | L23: Order by Oct 17. Size from measured current.
A24: Power | B24: Fuse holder, fuses, barrel input jack, switch, wire | C24: 1 | F24: =IF(AND(D24="",E24=""),"",C24*D24+E24) | G24: To buy | K24: P13: input connector, fused distribution | L24: Match the ASUS barrel size.
A25: Finishing | B25: Eyeballs (ready-made, or print and paint) | C25: 2 | F25: =IF(AND(D25="",E25=""),"",C25*D25+E25) | G25: To buy | K25: P2: eyeballs | L25: About 32 mm diameter to fit EyeMech.
A26: Enclosure | B26: Clear jar, cloche or acrylic cylinder | C26: 1 | F26: =IF(AND(D26="",E26=""),"",C26*D26+E26) | G26: To buy | K26: P14: transparent enclosure | L26: Size once head dimensions are set.
A27: Audio | B27: USB microphone | C27: 1 | F27: =IF(AND(D27="",E27=""),"",C27*D27+E27) | G27: To buy | K27: P12: microphone
A28: Audio | B28: Speaker and small amplifier | C28: 1 | F28: =IF(AND(D28="",E28=""),"",C28*D28+E28) | G28: To buy | K28: P12: speaker & amp
A29: Mold-making | B29: Rigid Wrap plaster bandage w/ header, 8 in | C29: 1 | D29: 11.51 | E29: 0.81 | F29: =IF(AND(D29="",E29=""),"",C29*D29+E29) -> 12.32 | G29: Arrived | H29: Wed Oct 21 | I29: Blick (Savannah) | K29: P8: mold sections | L29: Receipt 10/21, ticket 610. Price after Blick discount; tax is its share of the $4.28.
A30: Silicone & skin | B30: Smooth-On Dragon Skin FX-Pro | C30: 1 | D30: 35.09 | E30: 2.46 | F30: =IF(AND(D30="",E30=""),"",C30*D30+E30) -> 37.55 | G30: Arrived | H30: Wed Oct 21 | I30: Blick (Savannah) | K30: P2: silicone | L30: Receipt 10/21. THE skin silicone for the project (PLAN D21, 10/24): snap coupons and face casts. Replaces the Ecoflex 00-30 row (19).
A31: Mold-making | B31: Smooth-On Ease Release 200 spray, 12 oz | C31: 1 | D31: 14.39 | E31: 1.01 | F31: =IF(AND(D31="",E31=""),"",C31*D31+E31) -> 15.4 | G31: Arrived | H31: Wed Oct 21 | I31: Blick (Savannah) | K31: P2: thickener, sealer, release | L31: Receipt 10/21.
A32: Tools & workshop | B32: Pro Grade 1 in chip brushes, 24-pack | C32: 1 | D32: 11.99 | F32: =IF(AND(D32="",E32=""),"",C32*D32+E32) -> 11.99 | G32: Ordered | H32: Fri Oct 23 | I32: Amazon | K32: P2: mixing & mold tools | L32: Cart price, before tax.
A33: Tools & workshop | B33: Pro Grade 3/8 in acid brushes, 36-count | C33: 1 | D33: 6.49 | F33: =IF(AND(D33="",E33=""),"",C33*D33+E33) -> 6.49 | G33: Ordered | H33: Fri Oct 23 | I33: Amazon | K33: P2: mixing & mold tools | L33: Cart price, before tax.
A34: Tools & workshop | B34: MAXUS 500 g x 0.01 g pocket scale | C34: 1 | D34: 8.98 | F34: =IF(AND(D34="",E34=""),"",C34*D34+E34) -> 8.98 | G34: Ordered | H34: Fri Oct 23 | I34: Amazon | K34: P2: mixing & mold tools | L34: Cart price, before tax.
A35: Mold-making | B35: Zinsser Bulls Eye shellac spray, 12 oz | C35: 1 | D35: 14.96 | F35: =IF(AND(D35="",E35=""),"",C35*D35+E35) -> 14.96 | G35: Ordered | H35: Sat Oct 24 | I35: Amazon | K35: P8: seal mold | L35: DO NOT USE ON THE MOLD: Smooth-On says shellac makes silicone bond (10/24). Delayed to Mon 10/26; cancel or return.
A36: Tools & workshop | B36: 3M Aura 9205+ N95 respirator, 3-pack | C36: 1 | D36: 9.97 | F36: =IF(AND(D36="",E36=""),"",C36*D36+E36) -> 9.97 | G36: Ordered | H36: Fri Oct 23 | I36: Amazon | K36: P8: mold sections | L36: For mixing Ultracal (silica). Cart price, before tax.
A37: Silicone & skin | B37: Cab-O-Sil fumed silica thickener, 1 qt | C37: 1 | D37: 12.99 | F37: =IF(AND(D37="",E37=""),"",C37*D37+E37) -> 12.99 | G37: Ordered | H37: Fri Oct 23 | I37: Amazon | K37: P2: thickener, sealer, release | L37: Cart price, before tax.
A38: Tools & workshop | B38: MedPride nitrile gloves, medium, 100 | C38: 1 | D38: 9.99 | F38: =IF(AND(D38="",E38=""),"",C38*D38+E38) -> 9.99 | G38: Ordered | H38: Fri Oct 23 | I38: Amazon | K38: P2: mixing & mold tools | L38: Cart price, before tax.
A39: Finishing | B39: Master Airbrush Cool Runner II airbrush kit | C39: 1 | D39: 129.99 | F39: =IF(AND(D39="",E39=""),"",C39*D39+E39) -> 129.99 | G39: Ordered | H39: Fri Oct 23 | I39: Amazon | K39: P11: skin painting | L39: Cart price, before tax.
A40: Silicone & skin | B40: Smooth-On THI-VEX silicone thickener, 1 oz | C40: 1 | D40: 7.99 | F40: =IF(AND(D40="",E40=""),"",C40*D40+E40) -> 7.99 | G40: Ordered | H40: Mon Oct 26 | I40: Amazon | K40: P2: thickener, sealer, release | L40: Cart price, before tax.
A41: Tools & workshop | B41: #11 scalpel handle + 20 blades | C41: 1 | D41: 6.89 | F41: =IF(AND(D41="",E41=""),"",C41*D41+E41) -> 6.89 | G41: Ordered | H41: Fri Oct 23 | I41: Amazon | K41: P9: trim flashing | L41: Cart price, before tax.
...

Sheet Lists
A1: Categories | C1: Edit this list to add categories; the Purchases dropdown and Budget table use it.
A2: Servos
A3: Electronics
A4: Power
A5: Audio
A6: Hardware
A7: Silicone & skin
A8: Mold-making
A9: Sculpting
A10: Finishing
A11: Enclosure
A12: Tools & workshop
